# ES6第15课（Generator的基本用法）

之前，我们在编写异步方法的时候。如果异步方法相互依赖，会对我们代码造成很大的困扰。之后有了promise去改善我们的异步代码。再之后就有了Generator（生成器）。

当然，Generator本意并不是为了写异步代码使用的。但是他的诞生确实改变了我们编写代码的习惯。那么，就让我们一步步去解开它神秘的面纱吧。

尽管，在这之前，你得先了解Iterator接口的原理。我们都知道，for of循环可以迭代任何部署了Iterator接口的对象。那么，Iterator又是怎么生成的呢？让我们试着用我们的函数去构造一个Iterator对象。

## 编写一个Iterator函数

```javascript
function makeIterator(arr) {
    let i = 0;

    return {
        next() {
            let isDone = !(i<arr.length);
            let value = i<arr.length? [i, arr[i]]: undefined;
            i++;
            return {value,done: isDone}
        }
    }
}
let iterator = makeIterator([2,5,6]);

```
当我们不断的去调用next()方法的时候，这个函数将给我们返回以下的值

![image](http://pbl.yaojunrong.com/iterator%E6%8E%A5%E5%8F%A3.png)


# Generator生成器

既然了解了我们的Iterator接口的实现原理，那么，我们正式开始我们的Generator之旅吧

Generator其实是声明函数的一种方式，他和我们的普通函数有以下两个不同的地方：
1. 声明时带\*号。 即function\* (){};
2. 内部的yield表达式将会暂停整个函数的执行，并返回一个值。类似于return的作用。但是，return在一个函数中仅能返回一次，yield可以存在多个并每执行一个返回一个值。

代码如下：

```javascript

function* makePeople() {
    yield "找对象";
    yield "谈恋爱";
    yield "生猴子";
}

let iterator = makePeople();

```

那么实际上，当我们去执行makePeople的时候，函数并没有直接执行。而是返回了一个Iterator对象。那么，当我们去调用next方法的时候，它才开始执行，知道碰到第一个yield表达式之后暂停。当我们再次去执行next()方法的时候，才会继续往下执行。直到第二个yield表达式之后又暂停。
流程图如下：

![image](http://pbl.yaojunrong.com/yield.png);

那么，下面我们来实现generator生成器更高级一点的用法。

还是以刚才那个例子，我们去拓展开发。我们知道，就算实现了流程编程，我们也应该针对流程中发生的不同事情，进行不同的处理。那么，就需要有一个值可以去处理它。


```javascript
function* makePeople() {
    let isFind = yield "找对象的过程中......";

    console.log(isFind);
    let msg = ""
    if(isFind){
        console.log("找到对象了，可以好好谈一场恋爱了");
        msg = "谈恋爱";
    }
    else {
        msg = "世界没有爱了";
    }
    let talkLove = yield msg;

    if(talkLove){
        yield "生猴子";
    }
    else{
        yield "不活了";
    }
}

let iterator = makePeople();

```
调用next方法后执行结果如图:

![image](http://pbl.yaojunrong.com/yield%E9%AB%98%E7%BA%A7.png)

可以发现isFind打印为undefined。所以导致我们的函数往下走的时候，全部走向了另一个方向。

这是因为，尽管我们调用next方法能得到yield表达式后的值。但是yield表达式本身是不反悔任何内容的。所以，idFind并没有任何值。那么，要想给isFind赋值，就必须在调用这个next方法的同时，将值传入，这时候，值将作为上一个yield的返回值。

例如，一个幸运的童鞋执行这个函数得到的结果应该是.
![image](http://pbl.yaojunrong.com/next.png)

## generator的错误处理

我们知道，在我们异步代码执行的过程中，是可能出错的，那么有没有办法去捕获这个错误并作出一些处理呢？答案是可以的。

我们讲上述的代码故意改错两个地方，将第二步和第三步引用的变量弄错，然后在外部和内部同时捕获这些错误，看一看得到什么结果。

```javascript
function* makePeople() {
    let isFind = yield "找对象的过程中......";

    let msg = "";
    try{
        if(isFin){
            console.log("找到对象了，可以好好谈一场恋爱了");
            msg = "谈恋爱";
        }
        else {
            msg = "世界没有爱了";
        }
        let talkLove = yield msg;
    }catch(err){
        console.log(err, "内部")
    }
    
    if(talkLov){
        yield "生猴子";
    }
    else{
        yield "不活了";
    }
}

let iterator = makePeople();
console.log(iterator.next());
try{
    console.log(iterator.next())
    console.log(iterator.next())
}catch(err){
    console.log(err,"外部");
}

```

![image](http://pbl.yaojunrong.com/%E8%BF%AD%E4%BB%A3%E5%99%A8%E9%94%99%E8%AF%AF.png)

这是因为，当我们的外部的代码开始执行的时候，第一个错误，由于在内部有相应的错误捕获。那么，内部的更具体，所以将错误交给内部处理。但是第二个错误处理内部并没有给出相应的错误处理程序，那么，就交给外部的错误处理程序去处理错误。


## 使用Generator控制异步操作

